Workbook
Name Slicer_Governorate1: #N/A
Name Slicer_Year1: #N/A

Sheet Dim_Governorate
A1: Governorate_Key | B1: Governorate ID | C1: Governorate
A2: 1 | B2: AL002 | C2: Alexandria
A3: 2 | B3: AS018 | C3: Asyout
A4: 3 | B4: AW021 | C4: Aswan
A5: 4 | B5: BH012 | C5: Behera
A6: 5 | B6: BS015 | C6: Beni Suef
A7: 6 | B7: CA001 | C7: Cairo
A8: 7 | B8: DK006 | C8: Dakahlia
A9: 8 | B9: DM005 | C9: Damietta
A10: 9 | B10: FY016 | C10: Fayoum
A11: 10 | B11: GH010 | C11: Gharbia
A12: 11 | B12: GZ014 | C12: Giza
A13: 12 | B13: IS013 | C13: Ismailia
... A28: 27 | B28: WG024 | C28: Elwadi ElGidid

Sheet Dim_Year
A1: Year_ID | B1: Year
A2: 1 | B2: 2022
A3: 2 | B3: 2023
A4: 3 | B4: 2024
A5: 4 | B5: 2025

Sheet Dim_Month
A1: Month_ID | B1: Month
A2: 1 | B2: January
A3: 2 | B3: February
A4: 3 | B4: March
A5: 4 | B5: April
A6: 5 | B6: May
A7: 6 | B7: June
A8: 7 | B8: July
A9: 8 | B9: August
A10: 9 | B10: September
A11: 10 | B11: October
A12: 11 | B12: November
A13: 12 | B13: December

Sheet Dim_Gender
A1: Gender_ID | B1: Gender
A2: 1 | B2: Female
A3: 2 | B3: Male

Sheet Dim_Age
A1: Age_ID | B1: Age_Group
A2: 1 | B2: 0-5
A3: 2 | B3: 5-15
A4: 3 | B4: 15-25
A5: 4 | B5: 25-35
A6: 5 | B6: 35-45
A7: 6 | B7: 45-55
A8: 7 | B8: 55-65
A9: 8 | B9: 65+

Sheet Dim_Road_User
A1: RoadUser_ID | B1: Road_User_Type
A2: 1 | B2: Driver
A3: 2 | B3: Rider
A4: 3 | B4: Pedestrian
A5: 4 | B5: Other

Sheet Dim_Vehicle
A1: Vehicle_ID | B1: Vehicle_Type
A2: 1 | B2: Car
A3: 2 | B3: Train
A4: 3 | B4: Bicycle
A5: 4 | B5: Other

Sheet Fact_Monthly
A1: Governorate_Key | B1: Year_ID | C1: Month_ID | D1: Injuries | E1: Deaths
A2: 20 | B2: 1 | C2: 1 | D2: 0 | E2: 0
A3: 20 | B3: 3 | C3: 1 | D3: 0 | E3: 1
A4: 20 | B4: 1 | C4: 2 | D4: 0 | E4: 0
A5: 20 | B5: 3 | C5: 2 | D5: 0 | E5: 1
A6: 20 | B6: 1 | C6: 3 | D6: 0 | E6: 0
A7: 20 | B7: 3 | C7: 3 | D7: 0 | E7: 5
A8: 20 | B8: 1 | C8: 4 | D8: 0 | E8: 0
A9: 20 | B9: 3 | C9: 4 | D9: 0 | E9: 6
A10: 20 | B10: 1 | C10: 5 | D10: 0 | E10: 0
A11: 20 | B11: 3 | C11: 5 | D11: 0 | E11: 3
A12: 20 | B12: 1 | C12: 6 | D12: 0 | E12: 0
A13: 20 | B13: 3 | C13: 6 | D13: 0 | E13: 3
... A1297: 24 | B1297: 4 | C1297: 12 | D1297: 20 | E1297: 4

Sheet Fact_Age
A1: Governorate_Key | B1: Year_ID | C1: Age_ID | D1: Injuries | E1: Deaths
A2: 6 | B2: 1 | C2: 1 | D2: 128 | E2: 17
A3: 6 | B3: 1 | C3: 2 | D3: 1 | E3: 50
A4: 6 | B4: 1 | C4: 3 | D4: 47 | E4: 180
A5: 6 | B5: 1 | C5: 4 | D5: 65 | E5: 144
A6: 6 | B6: 1 | C6: 5 | D6: 45 | E6: 121
A7: 6 | B7: 1 | C7: 6 | D7: 23 | E7: 96
A8: 6 | B8: 1 | C8: 7 | D8: 11 | E8: 105
A9: 6 | B9: 1 | C9: 8 | D9: 2 | E9: 90
A10: 1 | B10: 1 | C10: 1 | D10: 79 | E10: 16
A11: 1 | B11: 1 | C11: 2 | D11: 216 | E11: 42
A12: 1 | B12: 1 | C12: 3 | D12: 929 | E12: 144
A13: 1 | B13: 1 | C13: 4 | D13: 736 | E13: 110
... A865: 24 | B865: 4 | C865: 8 | D865: 8 | E865: 4

Sheet Fact_Gender
A1: Governorate_Key | B1: Year_ID | C1: Gender_ID | D1: Injuries | E1: Deaths
A2: 6 | B2: 1 | C2: 2 | D2: 238 | E2: 142
A3: 6 | B3: 1 | C3: 1 | D3: 84 | E3: 661
A4: 1 | B4: 1 | C4: 2 | D4: 2832 | E4: 129
A5: 1 | B5: 1 | C5: 1 | D5: 800 | E5: 579
A6: 20 | B6: 1 | C6: 2 | D6: 0 | E6: 0
A7: 20 | B7: 1 | C7: 1 | D7: 0 | E7: 0
A8: 26 | B8: 1 | C8: 2 | D8: 929 | E8: 42
A9: 26 | B9: 1 | C9: 1 | D9: 239 | E9: 211
A10: 8 | B10: 1 | C10: 2 | D10: 1821 | E10: 22
A11: 12 | B11: 1 | C11: 1 | D11: 70 | E11: 268
A12: 8 | B12: 1 | C12: 1 | D12: 268 | E12: 104
A13: 12 | B13: 1 | C13: 2 | D13: 291 | E13: 65
... A217: 24 | B217: 4 | C217: 1 | D217: 95 | E217: 12

Sheet Fact_RoadUser
A1: Governorate_Key | B1: Year_ID | C1: RoadUser_ID | D1: Injuries | E1: Deaths
A2: 6 | B2: 1 | C2: 1 | D2: 6 | E2: 125
A3: 6 | B3: 1 | C3: 2 | D3: 1 | E3: 117
A4: 6 | B4: 1 | C4: 3 | D4: 12 | E4: 328
A5: 6 | B5: 1 | C5: 4 | D5: 303 | E5: 233
A6: 1 | B6: 1 | C6: 1 | D6: 263 | E6: 109
A7: 1 | B7: 1 | C7: 2 | D7: 1841 | E7: 61
A8: 1 | B8: 1 | C8: 3 | D8: 1471 | E8: 441
A9: 1 | B9: 1 | C9: 4 | D9: 57 | E9: 97
A10: 20 | B10: 1 | C10: 1 | D10: 0 | E10: 0
A11: 20 | B11: 1 | C11: 2 | D11: 0 | E11: 0
A12: 20 | B12: 1 | C12: 3 | D12: 0 | E12: 0
A13: 20 | B13: 1 | C13: 4 | D13: 0 | E13: 0
... A433: 24 | B433: 4 | C433: 4 | D433: 12 | E433: 3

Sheet Fact_Vehicle
A1: Governorate_Key | B1: Year_ID | C1: Vehicle_ID | D1: Injuries | E1: Deaths
A2: 6 | B2: 1 | C2: 1 | D2: 10 | E2: 467
A3: 6 | B3: 1 | C3: 2 | D3: 0 | E3: 3
A4: 6 | B4: 1 | C4: 3 | D4: 2 | E4: 73
A5: 6 | B5: 1 | C5: 4 | D5: 310 | E5: 260
A6: 1 | B6: 1 | C6: 1 | D6: 2906 | E6: 473
A7: 1 | B7: 1 | C7: 2 | D7: 14 | E7: 37
A8: 1 | B8: 1 | C8: 3 | D8: 491 | E8: 70
A9: 1 | B9: 1 | C9: 4 | D9: 221 | E9: 128
A10: 20 | B10: 1 | C10: 1 | D10: 0 | E10: 0
A11: 20 | B11: 1 | C11: 2 | D11: 0 | E11: 0
A12: 20 | B12: 1 | C12: 3 | D12: 0 | E12: 0
A13: 20 | B13: 1 | C13: 4 | D13: 0 | E13: 0
... A433: 24 | B433: 4 | C433: 4 | D433: 79 | E433: 4

Sheet Fact_Population
A1: Governorate_Key | B1: Year_ID | C1: Gender_ID | D1: Population
A2: 6 | B2: 1 | C2: 2 | D2: 5217906
A3: 6 | B3: 1 | C3: 1 | D3: 4882175
A4: 1 | B4: 1 | C4: 2 | D4: 2799938
A5: 1 | B5: 1 | C5: 1 | D5: 2669492
A6: 20 | B6: 1 | C6: 2 | D6: 401962
A7: 20 | B7: 1 | C7: 1 | D7: 381460
A8: 26 | B8: 1 | C8: 2 | D8: 399093
A9: 26 | B9: 1 | C9: 1 | D9: 379882
A10: 8 | B10: 1 | C10: 2 | D10: 817156
A11: 8 | B11: 1 | C11: 1 | D11: 776416
A12: 7 | B12: 1 | C12: 2 | D12: 3522351
A13: 7 | B13: 1 | C13: 1 | D13: 3408094
... A217: 24 | B217: 4 | C217: 1 | D217: 59604

Sheet Fact_Ambulance
A1: Governorate_Key | B1: Year_ID | C1: Number Of Ambulances | D1: Number Of Ambulance Points
A2: 6 | B2: 1 | C2: 297 | D2: 154
A3: 1 | B3: 1 | C3: 114 | D3: 58
A4: 20 | B4: 1 | C4: 49 | D4: 24
A5: 26 | B5: 1 | C5: 71 | D5: 35
A6: 8 | B6: 1 | C6: 80 | D6: 37
A7: 7 | B7: 1 | C7: 127 | D7: 89
A8: 23 | B8: 1 | C8: 159 | D8: 102
A9: 13 | B9: 1 | C9: 98 | D9: 70
A10: 14 | B10: 1 | C10: 85 | D10: 48
A11: 10 | B11: 1 | C11: 111 | D11: 63
A12: 17 | B12: 1 | C12: 108 | D12: 65
A13: 4 | B13: 1 | C13: 133 | D13: 91
... A109: 24 | B109: 4 | C109: 79 | D109: 47

Sheet Sheet6
A1: Data returned for Sum of Number Of Ambulances, Damietta (First 1000 rows).
A3: T_Fact_Ambulance[Governorate_Key] | B3: T_Fact_Ambulance[Year_ID] | C3: T_Fact_Ambulance[Number Of Ambulances] | D3: T_Fact_Ambulance[Number Of Ambulance Points]
A4: 8 | B4: 1 | C4: 80 | D4: 37
A5: 8 | B5: 2 | C5: 87 | D5: 37
A6: 8 | B6: 3 | C6: 94 | D6: 41
A7: 8 | B7: 4 | C7: 93 | D7: 41

Sheet Sheet4
A3: Row Labels | B3: Sum of Number Of Ambulances | D3: averg
A4: Cairo | B4: 1222 | D4: =AVEDEV(B4:B30) -> 114.19753 | G4: Row Labels | H4: Sum of Number Of Ambulance Points | J4: averg
A5: Giza | B5: 865 | G5: Cairo | H5: 727 | J5: =AVEDEV(H5:H31) -> 79.209877
A6: Sharkia | B6: 705 | G6: Giza | H6: 490
A7: Behera | B7: 538 | G7: Sharkia | H7: 402
A8: Dakahlia | B8: 515 | D8: =A4 -> Cairo | G8: Behera | H8: 366
A9: Matrouh | B9: 489 | G9: Dakahlia | H9: 354 | J9: =G5 -> Cairo
A10: Gharbia | B10: 481 | G10: Kalyoubia | H10: 276
A11: Alexandria | B11: 479 | G11: Qena | H11: 265
A12: Aswan | B12: 470 | G12: Matrouh | H12: 264
A13: Suhag | B13: 463 | G13: Menoufia | H13: 262
A14: Asyout | B14: 462 | G14: Gharbia | H14: 259
A15: Menia | B15: 456 | G15: Suhag | H15: 248
A16: Menoufia | B16: 442 | G16: Alexandria | H16: 236
A17: Ismailia | B17: 440 | G17: Menia | H17: 233
A18: Qena | B18: 431 | G18: Fayoum | H18: 226
A19: Kalyoubia | B19: 426 | G19: Ismailia | H19: 222
A20: Red Sea | B20: 423 | G20: Elwadi ElGidid | H20: 221
A21: North Sinai | B21: 410 | G21: Beni Suef | H21: 209
... A31: Grand Total | B31: 12667 | G31: Port Said | H31: 94
G32: Grand Total | H32: 7010
A39: Row Labels | B39: Sum of Number Of Ambulances | G39: Row Labels | H39: Sum of Number Of Ambulance Points
A40: Cairo | B40: 1222 | G40: Port Said | H40: 94
A41: Giza | B41: 865 | G41: Damietta | H41: 156
A42: Sharkia | B42: 705 | G42: Suez | H42: 157
A43: Behera | B43: 538 | G43: Luxor | H43: 170
A44: Dakahlia | B44: 515 | G44: South Sinai | H44: 177
A45: Matrouh | B45: 489 | G45: Aswan | H45: 195
A46: Gharbia | B46: 481 | G46: Red Sea | H46: 197
A47: Alexandria | B47: 479 | G47: North Sinai | H47: 200
A48: Aswan | B48: 470 | G48: Asyout | H48: 201
A49: Suhag | B49: 463 | G49: Kafr ElSheikh | H49: 203
A50: Asyout | B50: 462 | G50: Beni Suef | H50: 209
A51: Menia | B51: 456 | G51: Elwadi ElGidid | H51: 221
... A67: Grand Total | B67: 12667 | G67: Grand Total | H67: 7010
A77: Row Labels | B77: Sum of Number Of Ambulances | C77: Sum of Number Of Ambulance Points
A78: Alexandria | B78: 479 | C78: 236
A79: Aswan | B79: 470 | C79: 195
A80: Asyout | B80: 462 | C80: 201
A81: Behera | B81: 538 | C81: 366
...

Sheet Sheet5
G29: Ambulances by Governorate (Top 10)
V45: Governorate | W45: Sum of Number Of Ambulances | X45: Sum of Number Of Ambulance Points | Y45: Avg. Points per Ambulance
V46: Aswan | W46: 470 | X46: 195 | Y46: {=X46:X74/W46:W74} -> 0.41489362
V47: Alexandria | W47: 479 | X47: 236 | Y47: 0.49269311
V48: Asyout | W48: 462 | X48: 201 | Y48: 0.43506494
V49: Behera | W49: 538 | X49: 366 | Y49: 0.6802974
V50: Beni Suef | W50: 364 | X50: 209 | Y50: 0.57417582
V51: Cairo | W51: 1222 | X51: 727 | Y51: 0.59492635
V52: Dakahlia | W52: 515 | X52: 354 | Y52: 0.68737864
V53: Damietta | W53: 354 | X53: 156 | Y53: 0.44067797
V54: Elwadi ElGidid | W54: 355 | X54: 221 | Y54: 0.62253521
V55: Fayoum | W55: 315 | X55: 226 | Y55: 0.71746032
V56: Gharbia | W56: 481 | X56: 259 | Y56: 0.53846154
V57: Giza | W57: 865 | X57: 490 | Y57: 0.56647399
V58: Ismailia | W58: 440 | X58: 222 | Y58: 0.50454545
... V73: Grand Total | W73: 12667 | X73: 7010 | Y73: 0.55340649
Y74: #DIV/0!
H113: =GETPIVOTDATA("[Measures].[Sum of Number Of Ambulances]",Sheet4!$A$3) -> 12667
H118: =GETPIVOTDATA("[Measures].[Sum of Number Of Ambulance Points]",Sheet4!$G$4) -> 7010
H123: =Sheet4!D4 -> 114.19753
H126: =Sheet4!J5 -> 79.209877

Sheet Sheet1
A3: Sum of Number Of Ambulances
A4: 12667
A6: Sum of Number Of Ambulance Points
A7: 7010
A10: Sum of Number Of Ambulances
A11: 12667
A13: Sum of Number Of Ambulance Points
A14: 7010

Sheet pivot Table
A1: Total Population | D1: Totlal Injuries | G1: Total Deaths
A2: Year | B2: All | D2: Year | E2: All | G2: Year | H2: All | L2: Year | M2: All | X2: Year | Y2: All | AI2: Year | AJ2: All
A4: Row Labels | B4: Sum of Population | D4: Row Labels | E4: Sum of Injuries | G4: Row Labels | H4: Sum of Deaths | L4: Row Labels | M4: Sum of Injuries | N4: Sum of Population | O4: Injury Rate / 100K | S4: Row Labels | T4: Injury Rate / 100K | X4: Row Labels | Y4: Sum of Deaths | Z4: Sum of Population | AA4: Death Rate / 100K | AE4: Row Labels | AF4: Death Rate / 100K | AI4: Row Labels | AJ4: Sum of Population | AK4: Sum of Injuries | AN4: Row Labels | AO4: Sum of Population | AP4: Sum of Injuries | AT4: Row Labels | AU4: Sum of Population | AV4: Sum of Deaths | AY4: Row Labels | AZ4: Sum of Population | BA4: Sum of Deaths
A5: Alexandria | B5: 22201472 | D5: Alexandria | E5: 13686 | G5: Alexandria | H5: 1942 | L5: Alexandria | M5: 13686 | N5: 22201472 | O5: =M5/N5*100000 -> 61.644561 | S5: South Sinai | T5: 579.89114 | X5: Alexandria | Y5: 1942 | Z5: 22201472 | AA5: =Y5/Z5*100000 -> 8.7471678 | AE5: South Sinai | AF5: 61.164556 | AI5: Alexandria | AJ5: 22201472 | AK5: 13686 | AN5: Alexandria | AO5: 22201472 | AP5: 13686 | AT5: Alexandria | AU5: 22201472 | AV5: 1942 | AY5: Alexandria | AZ5: 22201472 | BA5: 1942
A6: Aswan | B6: 6633100 | D6: Aswan | E6: 861 | G6: Aswan | H6: 651 | L6: Aswan | M6: 861 | N6: 6633100 | O6: =M6/N6*100000 -> 12.980356 | S6: Red Sea | T6: 440.73647 | X6: Aswan | Y6: 651 | Z6: 6633100 | AA6: =Y6/Z6*100000 -> 9.8144156 | AE6: Matrouh | AF6: 45.839841 | AI6: Aswan | AJ6: 6633100 | AK6: 861 | AN6: Aswan | AO6: 6633100 | AP6: 861 | AT6: Aswan | AU6: 6633100 | AV6: 651 | AY6: Aswan | AZ6: 6633100 | BA6: 651
A7: Asyout | B7: 20278209 | D7: Asyout | E7: 18911 | G7: Asyout | H7: 861 | L7: Asyout | M7: 18911 | N7: 20278209 | O7: =M7/N7*100000 -> 93.257743 | S7: Matrouh | T7: 426.55131 | X7: Asyout | Y7: 861 | Z7: 20278209 | AA7: =Y7/Z7*100000 -> 4.2459371 | AE7: Elwadi ElGidid | AF7: 23.940269 | AI7: Asyout | AJ7: 20278209 | AK7: 18911 | AN7: Asyout | AO7: 20278209 | AP7: 18911 | AT7: Asyout | AU7: 20278209 | AV7: 861 | AY7: Asyout | AZ7: 20278209 | BA7: 861
A8: Behera | B8: 27538779 | D8: Behera | E8: 23427 | G8: Behera | H8: 2350 | L8: Behera | M8: 23427 | N8: 27538779 | O8: =M8/N8*100000 -> 85.069131 | S8: Damietta | T8: 332.74733 | X8: Behera | Y8: 2350 | Z8: 27538779 | AA8: =Y8/Z8*100000 -> 8.5334212 | AE8: Red Sea | AF8: 23.496052 | AI8: Behera | AJ8: 27538779 | AK8: 23427 | AN8: Behera | AO8: 27538779 | AP8: 23427 | AT8: Behera | AU8: 27538779 | AV8: 2350 | AY8: Behera | AZ8: 27538779 | BA8: 2350
A9: Beni Suef | B9: 14388992 | D9: Beni Suef | E9: 4492 | G9: Beni Suef | H9: 738 | L9: Beni Suef | M9: 4492 | N9: 14388992 | O9: =M9/N9*100000 -> 31.218309 | S9: Elwadi ElGidid | T9: 234.16576 | X9: Beni Suef | Y9: 738 | Z9: 14388992 | AA9: =Y9/Z9*100000 -> 5.1289208 | AE9: Ismailia | AF9: 19.08021 | AI9: Beni Suef | AJ9: 14388992 | AK9: 4492 | AN9: Beni Suef | AO9: 14388992 | AP9: 4492 | AT9: Beni Suef | AU9: 14388992 | AV9: 738 | AY9: Beni Suef | AZ9: 14388992 | BA9: 738
A10: Cairo | B10: 41030625 | D10: Cairo | E10: 3166 | G10: Cairo | H10: 3066 | L10: Cairo | M10: 3166 | N10: 41030625 | O10: =M10/N10*100000 -> 7.7161876 | S10: Dakahlia | T10: 211.90344 | X10: Cairo | Y10: 3066 | Z10: 41030625 | AA10: =Y10/Z10*100000 -> 7.4724672 | AE10: Damietta | AF10: 11.689161 | AI10: Cairo | AJ10: 41030625 | AK10: 3166 | AN10: Cairo | AO10: 41030625 | AP10: 3166 | AT10: Cairo | AU10: 41030625 | AV10: 3066 | AY10: Cairo | AZ10: 41030625 | BA10: 3066
A11: Dakahlia | B11: 28211435 | D11: Dakahlia | E11: 59781 | G11: Dakahlia | H11: 1978 | L11: Dakahlia | M11: 59781 | N11: 28211435 | O11: =M11/N11*100000 -> 211.90344 | S11: North Sinai | T11: 111.44916 | X11: Dakahlia | Y11: 1978 | Z11: 28211435 | AA11: =Y11/Z11*100000 -> 7.0113413 | AE11: Suez | AF11: 11.662194 | AI11: Dakahlia | AJ11: 28211435 | AK11: 59781 | AN11: Dakahlia | AO11: 28211435 | AP11: 59781 | AT11: Dakahlia | AU11: 28211435 | AV11: 1978 | AY11: Dakahlia | AZ11: 28211435 | BA11: 1978
A12: Damietta | B12: 6476085 | D12: Damietta | E12: 21549 | G12: Damietta | H12: 757 | L12: Damietta | M12: 21549 | N12: 6476085 | O12: =M12/N12*100000 -> 332.74733 | S12: Kafr ElSheikh | T12: 103.96586 | X12: Damietta | Y12: 757 | Z12: 6476085 | AA12: =Y12/Z12*100000 -> 11.689161 | AE12: Aswan | AF12: 9.8144156 | AI12: Damietta | AJ12: 6476085 | AK12: 21549 | AN12: Damietta | AO12: 6476085 | AP12: 21549 | AT12: Damietta | AU12: 6476085 | AV12: 757 | AY12: Damietta | AZ12: 6476085 | BA12: 757
A13: Elwadi ElGidid | B13: 1069328 | D13: Elwadi ElGidid | E13: 2504 | G13: Elwadi ElGidid | H13: 256 | L13: Elwadi ElGidid | M13: 2504 | N13: 1069328 | O13: =M13/N13*100000 -> 234.16576 | S13: Sharkia | T13: 98.13388 | X13: Elwadi ElGidid | Y13: 256 | Z13: 1069328 | AA13: =Y13/Z13*100000 -> 23.940269 | AE13: Alexandria | AF13: 8.7471678 | AI13: Elwadi ElGidid | AJ13: 1069328 | AK13: 2504 | AN13: Elwadi ElGidid | AO13: 1069328 | AP13: 2504 | AT13: Elwadi ElGidid | AU13: 1069328 | AV13: 256 | AY13: Elwadi ElGidid | AZ13: 1069328 | BA13: 256
A14: Fayoum | B14: 16340913 | D14: Fayoum | E14: 772 | G14: Fayoum | H14: 701 | L14: Fayoum | M14: 772 | N14: 16340913 | O14: =M14/N14*100000 -> 4.7243382 | S14: Asyout | T14: 93.257743 | X14: Fayoum | Y14: 701 | Z14: 16340913 | AA14: =Y14/Z14*100000 -> 4.289846 | AE14: Behera | AF14: 8.5334212 | AI14: Fayoum | AJ14: 16340913 | AK14: 772 | AN14: Fayoum | AO14: 16340913 | AP14: 772 | AT14: Fayoum | AU14: 16340913 | AV14: 701 | AY14: Fayoum | AZ14: 16340913 | BA14: 701
A15: Gharbia | B15: 21762729 | D15: Gharbia | E15: 18651 | G15: Gharbia | H15: 1068 | L15: Gharbia | M15: 18651 | N15: 21762729 | O15: =M15/N15*100000 -> 85.701568 | S15: Suez | T15: 89.326099 | X15: Gharbia | Y15: 1068 | Z15: 21762729 | AA15: =Y15/Z15*100000 -> 4.9074728 | AE15: Cairo | AF15: 7.4724672 | AI15: Gharbia | AJ15: 21762729 | AK15: 18651 | AN15: Gharbia | AO15: 21762729 | AP15: 18651 | AT15: Gharbia | AU15: 21762729 | AV15: 1068 | AY15: Gharbia | AZ15: 21762729 | BA15: 1068
A16: Giza | B16: 38112087 | D16: Giza | E16: 13839 | G16: Giza | H16: 1729 | L16: Giza | M16: 13839 | N16: 38112087 | O16: =M16/N16*100000 -> 36.311315 | S16: Gharbia | T16: 85.701568 | X16: Giza | Y16: 1729 | Z16: 38112087 | AA16: =Y16/Z16*100000 -> 4.5366185 | AE16: Dakahlia | AF16: 7.0113413 | AI16: Giza | AJ16: 38112087 | AK16: 13839 | AN16: Giza | AO16: 38112087 | AP16: 13839 | AT16: Giza | AU16: 38112087 | AV16: 1729 | AY16: Giza | AZ16: 38112087 | BA16: 1729
... A31: Suhag | B31: 22937821 | D31: Suhag | E31: 17277 | G31: Suhag | H31: 483 | L31: Suhag | M31: 17277 | N31: 22937821 | O31: =M31/N31*100000 -> 75.321017 | S31: Port Said | T31: 0 | X31: Suhag | Y31: 483 | Z31: 22937821 | AA31: =Y31/Z31*100000 -> 2.1056926 | AE31: Kafr ElSheikh | AF31: 1.5587488 | AI31: Suhag | AJ31: 22937821 | AK31: 17277 | AN31: Suhag | AO31: 22937821 | AP31: 17277 | AT31: Suhag | AU31: 22937821 | AV31: 483 | AY31: Suhag | AZ31: 22937821 | BA31: 483
A32: Grand Total | B32: 421117623 | D32: Grand Total | E32: 287922 | G32: Grand Total | H32: 24712 | L32: Grand Total | M32: 287922 | N32: 421117623 | O32: =M32/N32*100000 -> 68.370922 | X32: Grand Total | Y32: 24712 | Z32: 421117623 | AA32: =Y32/Z32*100000 -> 5.8681942 | AI32: Grand Total | AJ32: 421117623 | AK32: 287922 | AT32: Grand Total | AU32: 421117623 | AV32: 24712
A36: Injury Rate ==> | B36: =E32/B32*100000 -> 68.370922 | D36: Death Rate ==> | E36: =H32/B32*100000 -> 5.8681942
A43: Year | B43: All | E43: Year | F43: All
A45: Row Labels | B45: Injury Rate | E45: Row Labels | F45: Death
A46: South Sinai | B46: 579.89114 | E46: South Sinai | F46: 61.164556
A47: Red Sea | B47: 440.73647 | E47: Matrouh | F47: 45.839841
A48: Matrouh | B48: 426.55131 | E48: Elwadi ElGidid | F48: 23.940269
A49: Damietta | B49: 332.74733 | E49: Red Sea | F49: 23.496052
A50: Elwadi ElGidid | B50: 234.16576 | E50: Ismailia | F50: 19.08021
A51: Dakahlia | B51: 211.90344 | E51: Damietta | F51: 11.689161
A52: North Sinai | B52: 111.44916 | E52: Suez | F52: 11.662194
A53: Kafr ElSheikh | B53: 103.96586 | E53: Aswan | F53: 9.8144156
A54: Sharkia | B54: 98.13388 | E54: Alexandria | F54: 8.7471678
A55: Asyout | B55: 93.257743 | E55: Behera | F55: 8.5334212
A56: Suez | B56: 89.326099 | E56: Cairo | F56: 7.4724672
A57: Gharbia | B57: 85.701568 | E57: Dakahlia | F57: 7.0113413
... A73: Grand Total | B73: 68.370922 | E73: Grand Total | F73: 5.8681942

Sheet Dashboard2
G29: Ambulances by Governorate (Top 10)
V45: Governorate | W45: Sum of Number Of Ambulances | X45: Sum of Number Of Ambulance Points | Y45: Avg. Points per Ambulance
V46: Aswan | W46: 470 | X46: 195 | Y46: {=X46:X74/W46:W74} -> 0.41489362
V47: Alexandria | W47: 479 | X47: 236 | Y47: 0.49269311
V48: Asyout | W48: 462 | X48: 201 | Y48: 0.43506494
V49: Behera | W49: 538 | X49: 366 | Y49: 0.6802974
V50: Beni Suef | W50: 364 | X50: 209 | Y50: 0.57417582
V51: Cairo | W51: 1222 | X51: 727 | Y51: 0.59492635
V52: Dakahlia | W52: 515 | X52: 354 | Y52: 0.68737864
V53: Damietta | W53: 354 | X53: 156 | Y53: 0.44067797
V54: Elwadi ElGidid | W54: 355 | X54: 221 | Y54: 0.62253521
V55: Fayoum | W55: 315 | X55: 226 | Y55: 0.71746032
V56: Gharbia | W56: 481 | X56: 259 | Y56: 0.53846154
V57: Giza | W57: 865 | X57: 490 | Y57: 0.56647399
V58: Ismailia | W58: 440 | X58: 222 | Y58: 0.50454545
... V73: Grand Total | W73: 12667 | X73: 7010 | Y73: 0.55340649
Y74: #DIV/0!
H113: =GETPIVOTDATA("[Measures].[Sum of Number Of Ambulances]",Sheet4!$A$3) -> 12667
H118: =GETPIVOTDATA("[Measures].[Sum of Number Of Ambulance Points]",Sheet4!$G$4) -> 7010
H123: =Sheet4!D4 -> 114.19753
H126: =Sheet4!J5 -> 79.209877

Sheet Dashboard 6
AA8: =GETPIVOTDATA("[Measures].[Injury Rate]",Sheet4!$D$266) -> 68.370922
AA10: =GETPIVOTDATA("[Measures].[Death]",Sheet4!$D$252) -> 5.8681942
AB17: =GETPIVOTDATA("[Measures].[Sum of Injuries 2]",Sheet4!$C$193) -> 287922
AA19: =GETPIVOTDATA("[Measures].[Sum of Population]",Sheet4!$C$207) -> 421117623
AA20: =GETPIVOTDATA("[Measures].[Injury Rate]",Sheet4!$D$266) -> 68.370922
AB25: =GETPIVOTDATA("[Measures].[Sum of Injuries 2]",Sheet4!$C$193) -> 287922
AA32: =GETPIVOTDATA("[Measures].[Sum of Deaths 2]",Sheet4!$C$228) -> 24712
V36: Rank | W36: Governorates | X36: Injury
V37: 1 | W37: {='pivot Table'!A46:B55} -> South Sinai | X37: 579.89114
V38: 2 | W38: Red Sea | X38: 440.73647
V39: 3 | W39: Matrouh | X39: 426.55131
V40: 4 | W40: Damietta | X40: 332.74733
V41: 5 | W41: Elwadi ElGidid | X41: 234.16576
V42: 6 | W42: Dakahlia | X42: 211.90344
V43: 7 | W43: North Sinai | X43: 111.44916
V44: 8 | W44: Kafr ElSheikh | X44: 103.96586
V45: 9 | W45: Sharkia | X45: 98.13388
V46: 10 | W46: Asyout | X46: 93.257743
